<?xml version="1.0"?>
<!-- created with Phobos 0.7 -->
  <robot name="robotel2.0">

    <link name="link_Body">
      <inertial>
        <origin xyz="0 0 0" rpy="0 0 0"/>
        <mass value="10.0"/>
        <inertia ixx="3.63333" ixy="0" ixz="0" iyy="7.30833" iyz="0" izz="10.34167"/>
      </inertial>
      <visual name="Visual_Body">
        <origin xyz="0 0 0" rpy="0 0 0"/>
        <geometry>
          <box size="2.9 2.0 0.6"/>
        </geometry>
      </visual>
      <collision name="Collision_Body">
        <origin xyz="0 0 0" rpy="0 0 0"/>
        <geometry>
          <box size="2.9 2.0 0.6"/>
        </geometry>
      </collision>
    </link>

    <link name="link_FrontTurn">
      <inertial>
        <origin xyz="0 0 0" rpy="0 0 0"/>
        <mass value="0.01"/>
        <inertia ixx="7e-05" ixy="0" ixz="0" iyy="7e-05" iyz="0" izz="7e-05"/>
      </inertial>
      <visual name="FrontTurn">
        <origin xyz="0 0 0" rpy="0 0 0"/>
        <geometry>
          <box size="0.2 0.2 0.2"/>
        </geometry>
      </visual>
    </link>

    <link name="link_FrontWheel">
      <inertial>
        <origin xyz="0 0 0" rpy="0 0 0"/>
        <mass value="3.0"/>
        <inertia ixx="0.07951" ixy="0" ixz="0" iyy="0.07951" iyz="0" izz="0.07951"/>
      </inertial>
      <visual name="Visual_FrontWheel">
        <origin xyz="0 0 0" rpy="0 0 0"/>
        <geometry>
          <sphere radius="0.2574"/>
        </geometry>
      </visual>
      <collision name="Collision_FrontWheel">
        <origin xyz="0 0 0" rpy="0 0 0"/>
        <geometry>
          <sphere radius="0.2574"/>
        </geometry>
      </collision>
    </link>

    <link name="link_LWheel">
      <inertial>
        <origin xyz="0 0 0" rpy="0 0 0"/>
        <mass value="3.0"/>
        <inertia ixx="0.76" ixy="0" ixz="0" iyy="0.76" iyz="0" izz="1.5"/>
      </inertial>
      <visual name="Visual_LWheel">
        <origin xyz="0 0 0" rpy="0 0 0"/>
        <geometry>
          <cylinder radius="1.0" length="0.2"/>
        </geometry>
      </visual>
      <collision name="Collision_LWheel">
        <origin xyz="0 0 0" rpy="0 3.14159 0"/>
        <geometry>
          <cylinder radius="1.0" length="0.2"/>
        </geometry>
      </collision>
    </link>

    <link name="link_RWheel">
      <inertial>
        <origin xyz="0 0 0" rpy="0 0 0"/>
        <mass value="3.0"/>
        <inertia ixx="0.76" ixy="0" ixz="0" iyy="0.76" iyz="0" izz="1.5"/>
      </inertial>
      <visual name="Visual_RWheel">
        <origin xyz="0 0 0" rpy="0 0 0"/>
        <geometry>
          <cylinder radius="1.0" length="0.2"/>
        </geometry>
      </visual>
      <collision name="Collision_RWheel">
        <origin xyz="0 0 0" rpy="0 3.14159 0"/>
        <geometry>
          <cylinder radius="1.0" length="0.2"/>
        </geometry>
      </collision>
    </link>

    <link name="link_Sensor1">
      <inertial>
        <origin xyz="0 0 0" rpy="0 0 0"/>
        <mass value="1.0"/>
        <inertia ixx="0.02667" ixy="0" ixz="0" iyy="0.02667" iyz="0" izz="0.02667"/>
      </inertial>
      <visual name="Sensor1">
        <origin xyz="0 0 0" rpy="0 0 0"/>
        <geometry>
          <box size="0.4 0.4 0.4"/>
        </geometry>
      </visual>
      <collision name="Collision_Sensor1">
        <origin xyz="0 0 0" rpy="0 0 0"/>
        <geometry>
          <box size="0.4 0.4 0.4"/>
        </geometry>
      </collision>
    </link>

    <link name="link_Sensor2">
      <inertial>
        <origin xyz="0 0 0" rpy="0 0 0"/>
        <mass value="1.0"/>
        <inertia ixx="0.02667" ixy="0" ixz="0" iyy="0.02667" iyz="0" izz="0.02667"/>
      </inertial>
      <visual name="Sensor2">
        <origin xyz="0 0 0" rpy="0 0 0"/>
        <geometry>
          <box size="0.4 0.4 0.4"/>
        </geometry>
      </visual>
      <collision name="Collision_Sensor2">
        <origin xyz="0 0 0" rpy="0 0 0"/>
        <geometry>
          <box size="0.4 0.4 0.4"/>
        </geometry>
      </collision>
    </link>

    <link name="link_Sensor3">
      <inertial>
        <origin xyz="0 0 0" rpy="0 0 0"/>
        <mass value="1.0"/>
        <inertia ixx="0.02667" ixy="0" ixz="0" iyy="0.02667" iyz="0" izz="0.02667"/>
      </inertial>
      <visual name="Sensor3">
        <origin xyz="0 0 0" rpy="0 0 0"/>
        <geometry>
          <box size="0.4 0.4 0.4"/>
        </geometry>
      </visual>
      <collision name="Collision_Sensor3">
        <origin xyz="0 0 0" rpy="0 0 0"/>
        <geometry>
          <box size="0.4 0.4 0.4"/>
        </geometry>
      </collision>
    </link>

    <link name="link_Sensor4">
      <inertial>
        <origin xyz="0 0 0" rpy="0 0 0"/>
        <mass value="1.0"/>
        <inertia ixx="0.02667" ixy="0" ixz="0" iyy="0.02667" iyz="0" izz="0.02667"/>
      </inertial>
      <visual name="Sensor4">
        <origin xyz="0 0 0" rpy="0 0 0"/>
        <geometry>
          <box size="0.4 0.4 0.4"/>
        </geometry>
      </visual>
      <collision name="Collision_Sensor4">
        <origin xyz="0 0 0" rpy="0 0 0"/>
        <geometry>
          <box size="0.4 0.4 0.4"/>
        </geometry>
      </collision>
    </link>

    <link name="link_Sensor5">
      <inertial>
        <origin xyz="0 0 0" rpy="0 0 0"/>
        <mass value="1.0"/>
        <inertia ixx="0.02667" ixy="0" ixz="0" iyy="0.02667" iyz="0" izz="0.02667"/>
      </inertial>
      <visual name="Sensor5">
        <origin xyz="0 0 0" rpy="0 0 0"/>
        <geometry>
          <box size="0.4 0.4 0.4"/>
        </geometry>
      </visual>
      <collision name="Collision_Sensor5">
        <origin xyz="0 0 0" rpy="0 0 0"/>
        <geometry>
          <box size="0.4 0.4 0.4"/>
        </geometry>
      </collision>
    </link>

    <link name="link_Sensor6">
      <inertial>
        <origin xyz="0 0 0" rpy="0 0 0"/>
        <mass value="1.0"/>
        <inertia ixx="0.02667" ixy="0" ixz="0" iyy="0.02667" iyz="0" izz="0.02667"/>
      </inertial>
      <visual name="Sensor6">
        <origin xyz="0 0 0" rpy="0 0 0"/>
        <geometry>
          <box size="0.4 0.4 0.4"/>
        </geometry>
      </visual>
      <collision name="Collision_Sensor6">
        <origin xyz="0 0 0" rpy="0 0 0"/>
        <geometry>
          <box size="0.4 0.4 0.4"/>
        </geometry>
      </collision>
    </link>

    <joint name="link_FrontTurn" type="continuous">
      <origin xyz="1.12744 -0.00192 0.42406" rpy="0 0 0"/>
      <parent link="link_Body"/>
      <child link="link_FrontTurn"/>
	  <axis xyz="0 0 1.0"/>
      <limit lower="-45.0" upper="45.0" effort="10" velocity="100"/>
    </joint>

    <joint name="link_FrontWheel" type="continuous">
      <origin xyz="0 0 -1.0" rpy="1.5708 0 0"/>
      <parent link="link_FrontTurn"/>
      <child link="link_FrontWheel"/>
      <limit effort="10" velocity="100"/>
	  <axis xyz="0 0 1.0"/>
    </joint>

    <joint name="link_LWheel" type="continuous">
      <origin xyz="-1.25 1.2 0.1" rpy="1.5708 0 0"/>
      <parent link="link_Body"/>
      <child link="link_LWheel"/>
      <limit effort="0" velocity="0"/>
	  <axis xyz="0 0 -1.0"/>
    </joint>

    <joint name="link_RWheel" type="continuous">
      <origin xyz="-1.25 -1.2 0.1" rpy="1.5708 0 0"/>
      <parent link="link_Body"/>
      <child link="link_RWheel"/>
      <limit effort="0" velocity="0"/>
	  <axis xyz="0 0 -1.0"/>
    </joint>

    <joint name="link_Sensor1" type="fixed">
      <origin xyz="2.04744 1.49808 0.32406" rpy="0 0 0"/>
      <parent link="link_Body"/>
      <child link="link_Sensor1"/>
    </joint>

    <joint name="link_Sensor2" type="fixed">
      <origin xyz="2.04744 0.89808 0.32406" rpy="0 0 0"/>
      <parent link="link_Body"/>
      <child link="link_Sensor2"/>
    </joint>

    <joint name="link_Sensor3" type="fixed">
      <origin xyz="2.04744 0.29808 0.32406" rpy="0 0 0"/>
      <parent link="link_Body"/>
      <child link="link_Sensor3"/>
    </joint>

    <joint name="link_Sensor4" type="fixed">
      <origin xyz="2.04744 -0.30192 0.32406" rpy="0 0 0"/>
      <parent link="link_Body"/>
      <child link="link_Sensor4"/>
    </joint>

    <joint name="link_Sensor5" type="fixed">
      <origin xyz="2.04744 -0.90192 0.32406" rpy="0 0 0"/>
      <parent link="link_Body"/>
      <child link="link_Sensor5"/>
    </joint>

    <joint name="link_Sensor6" type="fixed">
      <origin xyz="2.04744 -1.50192 0.32406" rpy="0 0 0"/>
      <parent link="link_Body"/>
      <child link="link_Sensor6"/>
    </joint>

  </robot>
